import test from "./test.js";
import { nop } from "../lib/util.js";
import { Fiber, Scheduler } from "../lib/core.js";

function run(fiber) {
    const scheduler = new Scheduler();
    scheduler.resumeFiber(fiber);
    scheduler.update(0, Infinity);
}

test("Fiber.run()", t => {
    const fiber = new Fiber().
        sync(fiber => { fiber.value = 23; }).
        sync(fiber => { fiber.value += 17; });
    fiber.run().next();
    t.same(fiber.value, 40, "all ops ran");
});

test("Fiber.run() catches errors", t => {
    const fiber = new Fiber().
        sync(fiber => { fiber.value = 23; }).
        sync(() => { throw Error("AUGH"); }).
        sync(fiber => { fiber.value += 17; });
    fiber.run().next();
    t.same(fiber.error.message, "AUGH", "error property is set");
    t.same(fiber.value, 23, "ops after the error did not run");
});

test("Fiber.sync(f)", t => {
    const scheduler = new Scheduler();
    const fiber = new Fiber();
    t.equal(fiber, fiber.sync((...args) => {
        t.equal(args, [fiber, scheduler], "f gets called with the fiber and the scheduler");
    }), "returns the fiber to add more ops");
    fiber.run(scheduler).next();
});

test("Scheduler.update()", t => {
    run(new Fiber().
        sync(fiber => { fiber.value = 17; }).
        sync(({ value }) => { t.same(value, 17, "fiber has the expected value"); })
    );
});
